Workbook

Sheet Cómo usarla
B2: Plantilla de encuesta de clima laboral
B3: Una encuesta de 30 preguntas lista para imprimir, cargar y calcular. Gratis, de Censuma.
B5: Cómo usarla, en 5 pasos
B6: 1 | C6: Revisá las preguntas
C7: Leé la hoja Encuesta. Si una pregunta no aplica a tu organización, cambiale el texto, pero mantené una idea por pregunta.
B8: 2 | C8: Imprimila o pasala a un formulario
C9: La hoja Encuesta está lista para imprimir. Si preferís que se responda en línea, copiá las preguntas a un formulario anónimo.
B10: 3 | C10: Contá para qué es y que es anónima
C11: Antes de repartirla, explicá por qué la hacen, quién va a ver los resultados y que nadie va a saber qué respondió cada persona.
B12: 4 | C12: Cargá las respuestas
C13: En la hoja Respuestas va una fila por persona. Borrá antes las filas grises de ejemplo con la tecla Suprimir, sin eliminar las filas.
B14: 5 | C14: Leé los resultados y compartilos
C15: La hoja Resultados se calcula sola. Escribí cuántas personas invitaste para ver la participación, y contale al equipo lo que salió y qué van a hacer.
B17: La escala
B18: 1 | C18: Nada
B19: 2 | C19: Algo
B20: 3 | C20: Mucho
B21: 4 | C21: Completamente
C22: Una respuesta es favorable cuando vale 3 (Mucho) o 4 (Completamente).
C23: Son cuatro opciones y no hay punto medio: cada persona se inclina hacia un lado.
B25: Las 6 dimensiones
C26: Liderazgo (P1 a P5)
C27: Comunicación (P6 a P10)
C28: Trabajo en equipo (P11 a P15)
C29: Condiciones de trabajo (P16 a P20)
C30: Reconocimiento y desarrollo (P21 a P25)
C31: Compromiso y satisfacción (P26 a P30)
C32: Cinco preguntas por dimensión, más una de recomendación (eNPS) y dos abiertas.
B34: Cómo cuidar el anonimato
B35: • | C35: No pidas nombre, correo ni número de empleado en la encuesta.
B36: • | C36: Usá la columna Área solo con grupos grandes. Si un área tiene pocas personas, juntala con otra.
B37: • | C37: Nunca muestres resultados de un grupo tan chico que se pueda adivinar quién respondió.
B38: • | C38: Que las respuestas no las tabule la jefatura del área que se está evaluando.
B39: • | C39: Al compartir los comentarios abiertos, resumilos: un texto citado tal cual puede delatar a quien lo escribió.
B40: • | C40: Si la encuesta fue en papel, destruí las hojas cuando termines de cargarlas.
B42: Lo que esta plantilla no hace
B43: • | C43: No muestra resultados por área: un promedio general puede tapar al equipo que está pasándola mal.
B44: • | C44: No cruza filtros, por ejemplo un área con una antigüedad o un turno.
B45: • | C45: No compara una medición contra la anterior para ver si las cosas mejoraron.
B46: • | C46: No protege el anonimato sola: si alguien filtra un grupo chico, los datos quedan expuestos.
...

Sheet Encuesta
A1: Plantilla de encuesta de clima laboral
A2: Esta encuesta es anónima. No escribas tu nombre. Marcá con una X la opción que mejor describe tu experiencia en cada frase.
A3: Área (opcional):
A5: N.º | B5: Pregunta | C5: 1 Nada | D5: 2 Algo | E5: 3 Mucho | F5: 4 Completamente
A6: Liderazgo
A7: 1 | B7: Mi jefatura directa me explica con claridad qué espera de mi trabajo.
A8: 2 | B8: Mi jefatura me da comentarios que me sirven para mejorar.
A9: 3 | B9: La dirección explica las razones detrás de sus decisiones importantes.
A10: 4 | B10: Mi jefatura reparte las tareas de forma justa entre las personas del equipo.
A11: 5 | B11: Si cometo un error, puedo contárselo a mi jefatura sin miedo a represalias.
A12: Comunicación
A13: 6 | B13: Cuando algo va a cambiar en mi área, me lo explican antes de que pase.
A14: 7 | B14: La información que necesito para trabajar está disponible cuando la busco.
A15: 8 | B15: Cuando propongo una idea de mejora, se toma en cuenta.
A16: 9 | B16: Entiendo hacia dónde va la organización y cuáles son sus prioridades.
A17: 10 | B17: Las distintas áreas comparten entre sí la información necesaria.
A18: Trabajo en equipo
A19: 11 | B19: Las personas de mi equipo comparten lo que saben en vez de guardárselo.
A20: 12 | B20: Las personas de mi equipo cumplen lo que se comprometen a hacer.
A21: 13 | B21: En mi equipo se puede discutir una idea sin que se vuelva algo personal.
A22: 14 | B22: En mi equipo me incluyen en las conversaciones que tienen que ver con mi trabajo.
A23: 15 | B23: Coordinar tareas con otras áreas es sencillo.
A24: Condiciones de trabajo
A25: 16 | B25: Rara vez se me atrasa el trabajo por falta de materiales o por fallas en lo que uso.
A26: 17 | B26: La mayoría de los días puedo terminar mis tareas dentro de mi horario.
A27: 18 | B27: Puedo hacer mi trabajo sin poner en riesgo mi salud.
A28: 19 | B28: Mi horario me deja tiempo suficiente para mi familia y mis asuntos personales.
A29: 20 | B29: Los horarios y turnos se organizan de forma justa.
A30: Reconocimiento y desarrollo
A31: 21 | B31: Cuando hago un buen trabajo, alguien lo nota y me lo dice.
A32: 22 | B32: Entiendo cómo se decide lo que me pagan.
A33: 23 | B33: En el último año aprendí algo que me hace mejor en lo que hago.
A34: 24 | B34: Sé qué necesito hacer para crecer dentro de la organización.
A35: 25 | B35: Los ascensos y las oportunidades se asignan con criterios claros.
A36: Compromiso y satisfacción
A37: 26 | B37: Hablo bien de esta organización cuando estoy fuera del trabajo.
A38: 27 | B38: Mi trabajo tiene sentido para mí.
A39: 28 | B39: Si hoy me ofrecieran un puesto parecido en otro lugar, me quedaría aquí.
A40: 29 | B40: Hago más de lo que me piden cuando el equipo lo necesita.
A41: 30 | B41: Si tuviera que elegir de nuevo, volvería a aceptar este trabajo.
...

Sheet Respuestas
C1: Liderazgo | H1: Comunicación | M1: Trabajo en equipo | R1: Condiciones de trabajo | W1: Reconocimiento y desarrollo | AB1: Compromiso y satisfacción
A2: N.º | B2: Área | C2: P1 | D2: P2 | E2: P3 | F2: P4 | G2: P5 | H2: P6 | I2: P7 | J2: P8 | K2: P9 | L2: P10 | M2: P11 | N2: P12 | O2: P13 | P2: P14 | Q2: P15 | R2: P16 | S2: P17 | T2: P18 | U2: P19 | V2: P20 | W2: P21 | X2: P22 | Y2: P23 | Z2: P24 | AA2: P25 | AB2: P26 | AC2: P27 | AD2: P28 | AE2: P29 | AF2: P30 | AG2: eNPS | AH2: Abierta 1 | AI2: Abierta 2
A3: 1 | B3: Ejemplo: Ventas | C3: 3 | D3: 3 | E3: 3 | F3: 4 | G3: 4 | H3: 2 | I3: 3 | J3: 2 | K3: 3 | L3: 3 | M3: 3 | N3: 3 | O3: 2 | P3: 3 | Q3: 4 | R3: 2 | S3: 3 | T3: 1 | U3: 2 | V3: 2 | W3: 3 | X3: 3 | Y3: 3 | Z3: 2 | AA3: 1 | AB3: 3 | AC3: 3 | AD3: 3 | AE3: 3 | AF3: 2 | AG3: 7 | AH3: El buen ambiente con mis compañeros. | AI3: Que nos avisen antes de los cambios de turno.
A4: 2 | B4: Ejemplo: Operaciones | C4: 4 | D4: 4 | E4: 4 | F4: 4 | G4: 2 | H4: 3 | I4: 3 | J4: 3 | K4: 2 | L4: 3 | M4: 4 | N4: 3 | O4: 4 | P4: 4 | Q4: 2 | R4: 1 | S4: 4 | T4: 3 | U4: 3 | V4: 4 | W4: 3 | X4: 3 | Y4: 3 | Z4: 2 | AA4: 2 | AB4: 3 | AC4: 4 | AD4: 3 | AE4: 2 | AF4: 3 | AG4: 7
A5: 3 | B5: Ejemplo: Administración | C5: 3 | D5: 3 | E5: 1 | F5: 1 | G5: 3 | H5: 2 | I5: 1 | J5: 1 | K5: 2 | L5: 3 | M5: 3 | N5: 4 | O5: 3 | P5: 3 | Q5: 3 | R5: 2 | S5: 3 | T5: 2 | U5: 2 | V5: 3 | W5: 2 | X5: 3 | Y5: 1 | Z5: 3 | AA5: 2 | AB5: 4 | AC5: 3 | AD5: 2 | AE5: 4 | AF5: 3 | AG5: 10
A6: 4 | B6: Ejemplo: Atención al cliente | C6: 4 | D6: 4 | E6: 4 | F6: 3 | G6: 3 | H6: 4 | I6: 3 | J6: 4 | K6: 3 | L6: 3 | M6: 4 | N6: 3 | O6: 3 | P6: 4 | Q6: 3 | R6: 4 | S6: 4 | T6: 4 | U6: 3 | V6: 4 | W6: 4 | X6: 2 | Y6: 3 | Z6: 3 | AA6: 4 | AB6: 4 | AC6: 4 | AD6: 4 | AE6: 4 | AF6: 4 | AG6: 10 | AH6: La flexibilidad de horario. | AI6: Más capacitación para el puesto.
A7: 5 | B7: Ejemplo: Ventas | C7: 2 | D7: 2 | E7: 2 | F7: 1 | G7: 4 | H7: 4 | I7: 2 | J7: 2 | K7: 2 | L7: 2 | M7: 2 | N7: 3 | O7: 3 | P7: 2 | Q7: 2 | R7: 2 | S7: 1 | T7: 2 | U7: 1 | V7: 2 | W7: 2 | X7: 1 | Y7: 2 | Z7: 1 | AA7: 1 | AB7: 3 | AC7: 3 | AD7: 2 | AE7: 1 | AF7: 1 | AG7: 4
A8: 6 | B8: Ejemplo: Operaciones | C8: 3 | D8: 3 | E8: 2 | F8: 4 | G8: 3 | H8: 3 | I8: 4 | J8: 2 | K8: 3 | L8: 3 | M8: 3 | N8: 3 | O8: 4 | P8: 3 | Q8: 4 | R8: 1 | S8: 3 | T8: 3 | U8: 3 | V8: 3 | W8: 3 | X8: 3 | Y8: 3 | Z8: 2 | AA8: 3 | AB8: 4 | AC8: 4 | AD8: 4 | AE8: 3 | AF8: 4 | AG8: 7
A9: 7 | B9: Ejemplo: Administración | C9: 3 | D9: 3 | E9: 3 | F9: 3 | G9: 3 | H9: 1 | I9: 3 | J9: 2 | K9: 2 | L9: 1 | M9: 4 | N9: 4 | O9: 3 | P9: 1 | Q9: 3 | R9: 2 | S9: 2 | T9: 2 | U9: 3 | V9: 2 | W9: 2 | X9: 3 | Y9: 2 | Z9: 1 | AA9: 3 | AB9: 3 | AC9: 3 | AD9: 4 | AE9: 2 | AF9: 3 | AG9: 6 | AH9: Que mi trabajo ayuda a otras personas. | AI9: Que se reconozca más el esfuerzo.
A10: 8 | B10: Ejemplo: Atención al cliente | C10: 2 | D10: 1 | E10: 4 | F10: 2 | G10: 3 | H10: 3 | I10: 2 | J10: 2 | K10: 3 | L10: 2 | M10: 2 | N10: 4 | O10: 3 | P10: 2 | Q10: 2 | R10: 2 | S10: 3 | T10: 3 | U10: 3 | V10: 3 | W10: 1 | X10: 2 | Y10: 2 | Z10: 2 | AA10: 1 | AB10: 3 | AC10: 3 | AD10: 3 | AE10: 2 | AF10: 3 | AG10: 5
A11: 9 | B11: Ejemplo: Ventas | C11: 2 | D11: 1 | E11: 3 | F11: 2 | G11: 2 | H11: 2 | I11: 1 | J11: 3 | K11: 1 | L11: 2 | M11: 3 | N11: 3 | O11: 4 | P11: 3 | Q11: 3 | R11: 3 | S11: 2 | T11: 3 | U11: 2 | V11: 2 | W11: 1 | X11: 1 | Y11: 2 | Z11: 2 | AA11: 1 | AB11: 3 | AC11: 2 | AD11: 2 | AE11: 2 | AF11: 2 | AG11: 2
A12: 10 | B12: Ejemplo: Operaciones | C12: 4 | D12: 4 | E12: 3 | F12: 4 | G12: 3 | H12: 4 | I12: 4 | J12: 4 | K12: 3 | L12: 4 | M12: 4 | N12: 4 | O12: 4 | P12: 3 | Q12: 3 | R12: 3 | S12: 4 | T12: 4 | U12: 3 | V12: 4 | W12: 4 | X12: 3 | Y12: 2 | Z12: 3 | AA12: 3 | AB12: 3 | AC12: 4 | AD12: 3 | AE12: 4 | AF12: 4 | AG12: 8 | AH12: La estabilidad. | AI12: Mejores herramientas para trabajar.
A13: 11 | B13: Ejemplo: Administración | C13: 3 | D13: 4 | E13: 3 | F13: 3 | G13: 3 | H13: 3 | I13: 3 | J13: 4 | K13: 4 | L13: 3 | M13: 3 | N13: 4 | O13: 4 | P13: 3 | Q13: 3 | R13: 2 | S13: 3 | T13: 3 | U13: 3 | V13: 4 | W13: 3 | X13: 3 | Y13: 4 | Z13: 3 | AA13: 3 | AB13: 3 | AC13: 4 | AD13: 3 | AE13: 4 | AF13: 4 | AG13: 7
A14: 12 | B14: Ejemplo: Atención al cliente | C14: 4 | D14: 3 | E14: 3 | F14: 4 | G14: 4 | H14: 3 | I14: 4 | J14: 2 | K14: 3 | L14: 4 | M14: 3 | N14: 4 | O14: 4 | P14: 3 | Q14: 4 | R14: 3 | S14: 3 | T14: 3 | U14: 3 | V14: 3 | W14: 3 | X14: 3 | Y14: 3 | Z14: 3 | AA14: 4 | AB14: 3 | AC14: 4 | AD14: 3 | AE14: 4 | AF14: 3 | AG14: 9
A15: 13 | B15: Ejemplo: Ventas | C15: 3 | D15: 3 | E15: 2 | F15: 3 | G15: 2 | H15: 4 | I15: 3 | J15: 3 | K15: 2 | L15: 2 | M15: 2 | N15: 3 | O15: 4 | P15: 4 | Q15: 3 | R15: 3 | S15: 3 | T15: 3 | U15: 3 | V15: 4 | W15: 2 | X15: 1 | Y15: 2 | Z15: 2 | AA15: 3 | AB15: 4 | AC15: 3 | AD15: 2 | AE15: 2 | AF15: 3 | AG15: 8 | AH15: El buen ambiente con mis compañeros. | AI15: Que nos avisen antes de los cambios de turno.
A16: 14 | B16: Ejemplo: Operaciones | C16: 3 | D16: 3 | E16: 3 | F16: 3 | G16: 3 | H16: 3 | I16: 3 | J16: 4 | K16: 3 | L16: 3 | M16: 4 | N16: 3 | O16: 3 | P16: 4 | Q16: 4 | R16: 3 | S16: 2 | T16: 3 | U16: 4 | V16: 4 | W16: 4 | X16: 3 | Y16: 3 | Z16: 4 | AA16: 4 | AB16: 4 | AC16: 2 | AD16: 3 | AE16: 4 | AF16: 3 | AG16: 6
A17: 15 | B17: Ejemplo: Administración | C17: 2 | D17: 3 | E17: 3 | F17: 4 | G17: 2 | H17: 2 | I17: 3 | J17: 2 | K17: 2 | L17: 1 | M17: 4 | N17: 3 | O17: 2 | P17: 3 | Q17: 3 | R17: 2 | S17: 3 | T17: 3 | U17: 3 | V17: 3 | W17: 2 | X17: 3 | Y17: 3 | Z17: 2 | AA17: 3 | AB17: 3 | AC17: 3 | AD17: 3 | AE17: 3 | AF17: 3 | AG17: 5
A18: 16 | B18: Ejemplo: Atención al cliente | C18: 3 | D18: 3 | E18: 4 | F18: 4 | G18: 2 | H18: 3 | I18: 3 | J18: 2 | K18: 3 | L18: 4 | M18: 4 | N18: 3 | O18: 4 | P18: 3 | Q18: 4 | R18: 4 | S18: 4 | T18: 3 | U18: 3 | V18: 3 | W18: 4 | X18: 2 | Y18: 2 | Z18: 2 | AA18: 3 | AB18: 3 | AC18: 3 | AD18: 3 | AE18: 4 | AF18: 3 | AG18: 6 | AH18: La flexibilidad de horario. | AI18: Más capacitación para el puesto.
A19: 17 | B19: Ejemplo: Ventas | C19: 2 | D19: 2 | E19: 3 | F19: 2 | G19: 1 | H19: 2 | I19: 2 | J19: 3 | K19: 2 | L19: 2 | M19: 3 | N19: 3 | O19: 2 | P19: 3 | Q19: 3 | R19: 2 | S19: 2 | T19: 3 | U19: 3 | V19: 2 | W19: 2 | X19: 2 | Y19: 2 | Z19: 1 | AA19: 3 | AB19: 2 | AC19: 3 | AD19: 3 | AE19: 2 | AF19: 3 | AG19: 4
A20: 18 | B20: Ejemplo: Operaciones | C20: 2 | D20: 3 | E20: 3 | F20: 3 | G20: 4 | H20: 2 | I20: 2 | J20: 2 | K20: 2 | L20: 3 | M20: 3 | N20: 1 | O20: 2 | P20: 2 | Q20: 3 | R20: 3 | S20: 2 | T20: 2 | U20: 3 | V20: 4 | W20: 3 | X20: 3 | Y20: 2 | Z20: 2 | AA20: 1 | AB20: 2 | AC20: 1 | AD20: 3 | AE20: 3 | AF20: 2 | AG20: 6
A21: 19 | B21: Ejemplo: Administración | C21: 3 | D21: 2 | E21: 2 | F21: 1 | G21: 2 | H21: 2 | I21: 3 | J21: 4 | K21: 2 | L21: 1 | M21: 3 | N21: 3 | O21: 2 | P21: 2 | Q21: 4 | R21: 3 | S21: 2 | T21: 3 | U21: 1 | V21: 3 | W21: 4 | X21: 1 | Y21: 3 | Z21: 2 | AA21: 2 | AB21: 3 | AC21: 4 | AD21: 2 | AE21: 2 | AF21: 2 | AG21: 3 | AH21: Que mi trabajo ayuda a otras personas. | AI21: Que se reconozca más el esfuerzo.
A22: 20 | B22: Ejemplo: Atención al cliente | C22: 4 | D22: 3 | E22: 3 | F22: 4 | G22: 3 | H22: 4 | I22: 4 | J22: 4 | K22: 4 | L22: 2 | M22: 4 | N22: 4 | O22: 4 | P22: 4 | Q22: 4 | R22: 4 | S22: 4 | T22: 4 | U22: 4 | V22: 3 | W22: 3 | X22: 2 | Y22: 4 | Z22: 3 | AA22: 4 | AB22: 4 | AC22: 4 | AD22: 4 | AE22: 3 | AF22: 3 | AG22: 10
A23: 21
A24: 22
A25: 23
A26: 24
A27: 25
A28: 26
A29: 27
A30: 28
A31: 29
A32: 30
A33: 31
A34: 32
... A302: 300

Sheet Resultados
A1: Resultados
A2: Se calculan solos a partir de la hoja Respuestas. No hace falta tocar nada salvo las personas invitadas.
A4: Participación
B5: Personas invitadas (escribilo vos) | C5: 25
B6: Respuestas recibidas | C6: =SUMPRODUCT(--(MMULT(--(Respuestas!$C$3:$AG$302<>""),ROW($A$1:$A$31)^0)>0)) -> 20
B7: Participación | C7: =IFERROR(C6/C5,"") -> 0.8
A9: Resultado general
B10: % favorable general | C10: =IFERROR(COUNTIF(Respuestas!$C$3:$AF$302,">=3")/COUNT(Respuestas!$C$3:$AF$302),"") -> 0.68
B11: Porcentaje de respuestas con 3 o 4, sobre todas las respuestas de las 30 preguntas.
A13: eNPS
B14: Promotores (9 y 10) | C14: =IFERROR(COUNTIF(Respuestas!$AG$3:$AG$302,">=9")/COUNT(Respuestas!$AG$3:$AG$302),"") -> 0.2
B15: Pasivos (7 y 8) | C15: =IFERROR(COUNTIFS(Respuestas!$AG$3:$AG$302,">=7",Respuestas!$AG$3:$AG$302,"<=8")/COUNT(Respuestas!$AG$3:$AG$302),"") -> 0.3
B16: Detractores (0 a 6) | C16: =IFERROR(COUNTIF(Respuestas!$AG$3:$AG$302,"<=6")/COUNT(Respuestas!$AG$3:$AG$302),"") -> 0.5
B17: eNPS (% promotores menos % detractores) | C17: =IFERROR(ROUND((C14-C16)*100,0),"") -> -30
B18: Va de -100 a 100. Positivo quiere decir que hay más promotores que detractores.
A20: Por dimensión
B21: Dimensión | C21: % favorable | D21: Respuestas
A22: 1 | B22: Liderazgo | C22: =IFERROR(COUNTIF(Respuestas!$C$3:$G$302,">=3")/COUNT(Respuestas!$C$3:$G$302),"") -> 0.71 | D22: =COUNT(Respuestas!$C$3:$G$302) -> 100
A23: 2 | B23: Comunicación | C23: =IFERROR(COUNTIF(Respuestas!$H$3:$L$302,">=3")/COUNT(Respuestas!$H$3:$L$302),"") -> 0.57 | D23: =COUNT(Respuestas!$H$3:$L$302) -> 100
A24: 3 | B24: Trabajo en equipo | C24: =IFERROR(COUNTIF(Respuestas!$M$3:$Q$302,">=3")/COUNT(Respuestas!$M$3:$Q$302),"") -> 0.83 | D24: =COUNT(Respuestas!$M$3:$Q$302) -> 100
A25: 4 | B25: Condiciones de trabajo | C25: =IFERROR(COUNTIF(Respuestas!$R$3:$V$302,">=3")/COUNT(Respuestas!$R$3:$V$302),"") -> 0.68 | D25: =COUNT(Respuestas!$R$3:$V$302) -> 100
A26: 5 | B26: Reconocimiento y desarrollo | C26: =IFERROR(COUNTIF(Respuestas!$W$3:$AA$302,">=3")/COUNT(Respuestas!$W$3:$AA$302),"") -> 0.52 | D26: =COUNT(Respuestas!$W$3:$AA$302) -> 100
A27: 6 | B27: Compromiso y satisfacción | C27: =IFERROR(COUNTIF(Respuestas!$AB$3:$AF$302,">=3")/COUNT(Respuestas!$AB$3:$AF$302),"") -> 0.77 | D27: =COUNT(Respuestas!$AB$3:$AF$302) -> 100
A29: Por pregunta
B30: Pregunta | C30: % favorable | D30: Respuestas
A31: P1 | B31: Mi jefatura directa me explica con claridad qué espera de mi trabajo. | C31: =IFERROR(COUNTIF(Respuestas!$C$3:$C$302,">=3")/COUNT(Respuestas!$C$3:$C$302),"") -> 0.7 | D31: =COUNT(Respuestas!$C$3:$C$302) -> 20
A32: P2 | B32: Mi jefatura me da comentarios que me sirven para mejorar. | C32: =IFERROR(COUNTIF(Respuestas!$D$3:$D$302,">=3")/COUNT(Respuestas!$D$3:$D$302),"") -> 0.75 | D32: =COUNT(Respuestas!$D$3:$D$302) -> 20
A33: P3 | B33: La dirección explica las razones detrás de sus decisiones importantes. | C33: =IFERROR(COUNTIF(Respuestas!$E$3:$E$302,">=3")/COUNT(Respuestas!$E$3:$E$302),"") -> 0.75 | D33: =COUNT(Respuestas!$E$3:$E$302) -> 20
A34: P4 | B34: Mi jefatura reparte las tareas de forma justa entre las personas del equipo. | C34: =IFERROR(COUNTIF(Respuestas!$F$3:$F$302,">=3")/COUNT(Respuestas!$F$3:$F$302),"") -> 0.7 | D34: =COUNT(Respuestas!$F$3:$F$302) -> 20
A35: P5 | B35: Si cometo un error, puedo contárselo a mi jefatura sin miedo a represalias. | C35: =IFERROR(COUNTIF(Respuestas!$G$3:$G$302,">=3")/COUNT(Respuestas!$G$3:$G$302),"") -> 0.65 | D35: =COUNT(Respuestas!$G$3:$G$302) -> 20
A36: P6 | B36: Cuando algo va a cambiar en mi área, me lo explican antes de que pase. | C36: =IFERROR(COUNTIF(Respuestas!$H$3:$H$302,">=3")/COUNT(Respuestas!$H$3:$H$302),"") -> 0.6 | D36: =COUNT(Respuestas!$H$3:$H$302) -> 20
A37: P7 | B37: La información que necesito para trabajar está disponible cuando la busco. | C37: =IFERROR(COUNTIF(Respuestas!$I$3:$I$302,">=3")/COUNT(Respuestas!$I$3:$I$302),"") -> 0.7 | D37: =COUNT(Respuestas!$I$3:$I$302) -> 20
A38: P8 | B38: Cuando propongo una idea de mejora, se toma en cuenta. | C38: =IFERROR(COUNTIF(Respuestas!$J$3:$J$302,">=3")/COUNT(Respuestas!$J$3:$J$302),"") -> 0.5 | D38: =COUNT(Respuestas!$J$3:$J$302) -> 20
A39: P9 | B39: Entiendo hacia dónde va la organización y cuáles son sus prioridades. | C39: =IFERROR(COUNTIF(Respuestas!$K$3:$K$302,">=3")/COUNT(Respuestas!$K$3:$K$302),"") -> 0.5 | D39: =COUNT(Respuestas!$K$3:$K$302) -> 20
A40: P10 | B40: Las distintas áreas comparten entre sí la información necesaria. | C40: =IFERROR(COUNTIF(Respuestas!$L$3:$L$302,">=3")/COUNT(Respuestas!$L$3:$L$302),"") -> 0.55 | D40: =COUNT(Respuestas!$L$3:$L$302) -> 20
A41: P11 | B41: Las personas de mi equipo comparten lo que saben en vez de guardárselo. | C41: =IFERROR(COUNTIF(Respuestas!$M$3:$M$302,">=3")/COUNT(Respuestas!$M$3:$M$302),"") -> 0.85 | D41: =COUNT(Respuestas!$M$3:$M$302) -> 20
A42: P12 | B42: Las personas de mi equipo cumplen lo que se comprometen a hacer. | C42: =IFERROR(COUNTIF(Respuestas!$N$3:$N$302,">=3")/COUNT(Respuestas!$N$3:$N$302),"") -> 0.95 | D42: =COUNT(Respuestas!$N$3:$N$302) -> 20
A43: P13 | B43: En mi equipo se puede discutir una idea sin que se vuelva algo personal. | C43: =IFERROR(COUNTIF(Respuestas!$O$3:$O$302,">=3")/COUNT(Respuestas!$O$3:$O$302),"") -> 0.75 | D43: =COUNT(Respuestas!$O$3:$O$302) -> 20
A44: P14 | B44: En mi equipo me incluyen en las conversaciones que tienen que ver con mi trabajo. | C44: =IFERROR(COUNTIF(Respuestas!$P$3:$P$302,">=3")/COUNT(Respuestas!$P$3:$P$302),"") -> 0.75 | D44: =COUNT(Respuestas!$P$3:$P$302) -> 20
A45: P15 | B45: Coordinar tareas con otras áreas es sencillo. | C45: =IFERROR(COUNTIF(Respuestas!$Q$3:$Q$302,">=3")/COUNT(Respuestas!$Q$3:$Q$302),"") -> 0.85 | D45: =COUNT(Respuestas!$Q$3:$Q$302) -> 20
...
